<?xml version="1.0" encoding="utf-8"?>

<robot name="basic_link">

    <link name="base_link">
        <visual>
            <origin xyz="0.0 0.0 0.075" rpy="0.0 0.0 0.0"/>
            <geometry>
                <box size="0.1 0.12 0.15"/>             
            </geometry>
            <material name="brown">
                <color rgba="0.1 0.43 0.43 1.0" />
            </material>      
        </visual>
        <collision>
            <origin xyz="0.0 0.0 0.075" rpy="0.0 0.0 0.0"/>
            <geometry>
                <box size="0.1 0.12 0.15"/>             
            </geometry>          
        </collision>
        <inertial>
            <mass value="0.5"/>
            <origin xyz="0.0 0.0 0.0" rpy="0.0 0.0 0.0"/>
            <inertia ixx="0.1" ixy="0.0" ixz="0.0" iyy="1.0" iyz="0.0" izz="1.0"/> 
        </inertial>
    </link>

    <link name="link_1">
        <visual>
            <origin xyz="0.025 0.0 0.25" rpy="0.0 0.0 0.0"/>
            <geometry>
                <box size="0.05 0.05 0.5"/>             
            </geometry>
            <material name="red">
                <color rgba="0.5 0.0 0.0 1.0" />
            </material>      
        </visual>
        <collision>
            <origin xyz="0.025 0.0 0.25" rpy="0.0 0.0 0.0"/>
            <geometry>
                <box size="0.05 0.05 0.5"/>             
            </geometry>          
        </collision>
        <inertial>
            <mass value="0.3"/>
            <origin xyz="0.0 0.0 0.0" rpy="0.0 0.0 0.0"/>
            <inertia ixx="0.1" ixy="0.0" ixz="0.0" iyy="1.0" iyz="0.0" izz="1.0"/> 
        </inertial>
    </link>

    <link name="link_2">
        <visual>
            <origin xyz="0.025 0.0 0.15" rpy="0.0 0.0 0.0"/>
            <geometry>
                <box size="0.03 0.03 0.3"/>             
            </geometry>
            <material name="yellow">
                <color rgba="0.5 0.5 0.0 1.0" />
            </material>      
        </visual>
        <collision>
            <origin xyz="0.0 -0.20 0.0" rpy="0.0 0.0 0.0"/>
            <geometry>
                <box size="0.03 0.03 0.3"/>             
            </geometry>          
        </collision>
        <inertial>
            <mass value="0.1"/>
            <origin xyz="0.0 0.0 0.0" rpy="0.0 0.0 0.0"/>
            <inertia ixx="0.1" ixy="0.0" ixz="0.0" iyy="1.0" iyz="0.0" izz="1.0"/> 
        </inertial>
    </link>

    <joint name="base_link_to_link_1" type="revolute">
        <parent link="base_link"/>
        <child link="link_1"/>
        <axis xyz="1 0 0"/>
        <limit lower="-3.14159" upper="3.14159" velocity="50.0" effort="1000.0"/>
        <origin xyz="0.05 0 0.15" rpy="0 0 0"/>
    </joint>

    <joint name="link_1_to_link_2" type="revolute">
        <parent link="link_1"/>
        <child link="link_2"/>
        <axis xyz="1 0 0"/>
        <limit lower="-3.14159" upper="3.14159" velocity="50.0" effort="100.0"/>
        <origin xyz="-0.04 0.0 0.48" rpy="0 0 0"/>
    </joint>

</robot>