<?xml version="1.0" encoding="utf-8"?>

<robot name="robot_scara" xmlns:xacro="http://ros.org/wiki/xacro">
	
	<link name="world"/>

	<joint name="world_joint" type="fixed">
		<parent link="world" />
		<child link="base_link" />	
		<origin xyz="0.0 0.0 0.0" rpy="0.0 0.0 0.0" />
	</joint>
	
	<link name="base_link">
		<visual>
			<origin xyz="0.0 0.0 0.4353" rpy="0.0 0.0 0.0"/>
			
			<geometry>
				<box size="0.2 0.2 0.8"/>
			</geometry>

			<material name="red">
				<color rgba="1.0 0.0 0.0 1.0"/>
			</material>
		</visual>
		
		<collision>
			<origin xyz="0.0 0.0 0.4353" rpy="0.0 0.0 0.0"/>
			
			<geometry>
				<box size="0.2 0.2 0.8"/>
			</geometry>
		</collision>
		
		<inertial>
			<mass value="1.0"/>
	
			<origin xyz="0.0 0.0 0.0" rpy="0.0 0.0 0.0"/>
			
			<inertia ixx="1.0" ixy="0.0" ixz="0.0"
				iyy="1.0" iyz="0.0" izz="1.0"/>
		</inertial>
	</link>

	<link name="link_1">	
		<visual>
			<origin xyz="0.0 0.0 0.4353" rpy="0.0 0.0 0.0"/>
			
			<geometry>
				<box size="0.8 0.2 0.2"/>
			</geometry>

			<material name="green">
				<color rgba="0.0 1.0 0.0 1.0"/>
			</material>
		</visual>
			
		<collision>
			<origin xyz="0.0 0.0 0.4353" rpy="0.0 0.0 0.0"/>
			
			<geometry>
				<box size="0.2 0.2 0.8"/>
			</geometry>
		</collision>
			
		<inertial>
			<mass value="1.0"/>
			
			<origin xyz="0.0 0.0 0.0" rpy="0.0 0.0 0.0"/>
			
			<inertia ixx="1.0" ixy="0.0" ixz="0.0"
				iyy="1.0" iyz="0.0" izz="1.0"/>
		</inertial>
	</link>

	<joint name="link1_joint" type="revolute" >
		<parent link="base_link" />
		<child link="link_1" />
		<axis xyz="0.0 0.0 1.0" />
		<limit lower="-0.78" upper="0.78" velocity="30"
			effort="10" />
		<origin xyz="0.0 0.0 0.8706" rpy="0.0 0.0 0.0" />
	</joint>

	<link name="link_2">
		<visual>
			<origin xyz="0.0 0.0 0.4353" rpy="0.0 0.0 0.0"/>
			
			<geometry>
				<box size="0.8 0.2 0.2"/>
			</geometry>

			<material name="blue">
				<color rgba="0.0 0.0 1.0 1.0"/>
			</material>
		</visual>

		<collision>
			<origin xyz="0.0 0.0 0.4353" rpy="0.0 0.0 0.0"/>
			
			<geometry>
				<box size="0.2 0.2 0.8"/>
			</geometry>
		</collision>

		<inertial>
			<mass value="1.0"/>
			
			<origin xyz="0.0 0.0 0.0" rpy="0.0 0.0 0.0"/>
			
			<inertia ixx="1.0" ixy="0.0" ixz="0.0"
				iyy="1.0" iyz="0.0" izz="1.0"/>
		</inertial>
	</link>

	<joint name="link2_joint" type="revolute" >
		<parent link="link_1" />
		<child link="link_2" />
		<axis xyz="0.0 1.0 0.0" />
		<limit lower="-0.78" upper="0.78" velocity="30"
			effort="10" />
		<origin xyz="0.0 0.0 0.8706" rpy="0.0 0.0 0.0" />
	</joint>
	
	<link name="link_3">
		<visual>
			<origin xyz="0.0 0.0 0.4353" rpy="0.0 0.0 0.0"/>
			
			<geometry>
				<box size="0.8 0.2 0.2"/>
			</geometry>

			<material name="black">
				<color rgba="0.0 0.0 0.0 1.0"/>
			</material>
		</visual>

		<collision>
			<origin xyz="0.0 0.0 0.4353" rpy="0.0 0.0 0.0"/>
			
			<geometry>
				<box size="0.2 0.2 0.8"/>
			</geometry>
		</collision>

		<inertial>
			<mass value="1.0"/>
			
			<origin xyz="0.0 0.0 0.0" rpy="0.0 0.0 0.0"/>
			
			<inertia ixx="1.0" ixy="0.0" ixz="0.0"
				iyy="1.0" iyz="0.0" izz="1.0"/>
		</inertial>
	</link>

	<joint name="link3_joint" type="revolute" >
		<parent link="link_2" />
		<child link="link_3" />
		<axis xyz="0.0 1.0 0.0" />
		<limit lower="-0.78" upper="0.78" velocity="30"
			effort="10" />
		<origin xyz="0.0 0.0 0.8706" rpy="0.0 0.0 0.0" />
	</joint>

	<link name="P"/>

	<joint name="link_P_joint" type="fixed" >
		<parent link="link_3" />
		<child link="P" />
		<origin xyz="0.25 0.0 0.0" rpy="0.0 0.0 0.0" />
	</joint>
</robot>